Workbook
Name _2012.06.11___GFM_Indicator_List: 'Indicator Metadata'!$D$18:$J$36
Name _2012.06.11___GFM_Indicator_List_1: 'Indicator Metadata'!$D$18:$J$36
Name _2012.06.11___GFM_Indicator_List_2: 'Indicator Metadata'!$D$16:$J$36
Name CrisisList: 'Crisis Indicator Data'!$A$13:$A$28
Name CrisisType: VLOOKUP(#REF!,#REF!,2,FALSE)
Name CrisisType: VLOOKUP(#REF!,#REF!,2,FALSE)
Name iCrisisType: INDIRECT(CrisisType)
Name iCrisisType: INDIRECT('Data Reliability'!CrisisType)
Name iCrisisType: INDIRECT(CrisisType)
Name iCrisisType: INDIRECT(CrisisType)
Name iIcons_a5: INDIRECT(#REF!)
Name iIcons_a5: INDIRECT(#REF!)
Name iIcons_a8: INDIRECT(#REF!)
Name iIcons_a8: INDIRECT(#REF!)

Sheet INFORM Severity - country
A1: ="INFORM Severity Index - all countries. Release: "&About!$A$5&"" -> INFORM Severity Index - all countries. Release: August 2026
A2: CRISIS | B2: CRISIS ID | C2: COUNTRY | D2: ISO3 | E2: DRIVERS | F2: INFORM Severity Index | G2: INFORM Severity category | H2: INFORM Severity category | I2: Trend (last 3 months) | J2: Reliability | K2: Impact of the crisis | L2: Geographical | M2: Human | N2: Conditions of people affected | O2: People in need | P2: Concentration of conditions | Q2: Complexity of the crisis | R2: Society and safety | S2: Operating environment | T2: Regions | U2: Last updated
A3: Weights
A4: (a-z) | D4: (a-z) | F4: (1-10) | G4: (1-5) | H4: (Very Low-Very High) | I4: (Decreasing-Stable-Increasing) | J4: (Very Low-Very High) | K4: (1-10) | L4: (1-10) | M4: (1-10) | N4: (1-10) | O4: (1-10) | P4: (1-10) | Q4: (1-10) | R4: (1-10) | S4: (1-10)
A5: {=IFERROR(INDEX(Lists!$B$2:$B$200,SMALL(IF(Lists!$H$2:$H$200="Yes",ROW(Lists!$B$2:$B$200)),ROW(1:1))-1,1),"")} -> Complex crisis in Afghanistan | B5: =VLOOKUP(A5,Lists!$B$2:$G$200,2,FALSE) -> AFG001 | C5: =VLOOKUP(B5,'INFORM Severity - hidden'!$C$5:$D$200,2,FALSE) -> Afghanistan | D5: =VLOOKUP(A5,Lists!$B$2:$G$200,3,FALSE) -> AFG | E5: =VLOOKUP(A5,Lists!$B$2:$G$200,5,FALSE) -> Conflict/ Violence,Political/economic crisis,Floods,Drought/drier conditions,Earthquake | F5: =IF(OR(N5="x",K5="x"),"x",ROUND((10-GEOMEAN(((10-K5)/10*9+1),((10-N5)/10*9+1),((10-N5)/10*9+1)))/9*7+Q5*0.3,1)) -> 9.2 | G5: {=_xlfn.IFS(F5="x", "x", F5<=2, 1, F5<=4, 2, F5<=6, 3, F5<=8, 4, F5<=10, 5)} -> 5 | H5: =IF(N5="x","x",IF(K5="x","x",(IF(G5=5,"Very High",IF(G5=4,"High",IF(G5=3,"Medium",IF(G5=2,"Low","Very Low"))))))) -> Very High | I5: =INDEX(Trends!$D$3:$D$404,MATCH(B5,Trends!$C$3:$C$404,0)) -> Increasing | J5: =VLOOKUP($B5,Reliability!$A$3:$I$300,9,FALSE) -> Very High | K5: =IF(OR(M5="x",L5="x"),"x",(10-GEOMEAN(((10-L5)/10*9+1),((10-M5)/10*9+1),((10-M5)/10*9+1)))/9*10) -> 9.5784237 | L5: =VLOOKUP($B5,'Impact of the crisis'!$C$6:$N$300,12,FALSE) -> 9.8548189 | M5: =VLOOKUP($B5,'Impact of the crisis'!$C$6:$AB$300,26,FALSE) -> 9.4181965 | N5: =VLOOKUP($B5,'Conditions of people affected'!$C$6:$R$300,16,FALSE) -> 9 | O5: =VLOOKUP($B5,'Conditions of people affected'!$C$6:$R$300,9,FALSE) -> 10 | P5: =VLOOKUP($B5,'Conditions of people affected'!$C$6:$R$300,15,FALSE) -> 8 | Q5: =IF(OR(S5="x",R5="x"),R5,(10-GEOMEAN(((10-R5)/10*9+1),((10-S5)/10*9+1)))/9*10) -> 9.2469267 | R5: =VLOOKUP($B5,'Complexity of the crisis'!$C$6:$AN$300,22,FALSE) -> 7.9834458 | S5: =VLOOKUP($B5,'Complexity of the crisis'!$C$6:$AN$300,38,FALSE) -> 10 | T5: =VLOOKUP(B5,Lists!$C$3:$E$300,3,FALSE) -> Asia | U5: =VLOOKUP(B5,'INFORM Severity - hidden'!$C$5:$V$300,20,FALSE) -> 46265
A6: {=IFERROR(INDEX(Lists!$B$2:$B$200,SMALL(IF(Lists!$H$2:$H$200="Yes",ROW(Lists!$B$2:$B$200)),ROW(2:2))-1,1),"")} -> Displacement from Eastern DRC | B6: =VLOOKUP(A6,Lists!$B$2:$G$200,2,FALSE) -> BDI004 | C6: =VLOOKUP(B6,'INFORM Severity - hidden'!$C$5:$D$200,2,FALSE) -> Burundi | D6: =VLOOKUP(A6,Lists!$B$2:$G$200,3,FALSE) -> BDI | E6: =VLOOKUP(A6,Lists!$B$2:$G$200,5,FALSE) -> International Displacement | F6: =IF(OR(N6="x",K6="x"),"x",ROUND((10-GEOMEAN(((10-K6)/10*9+1),((10-N6)/10*9+1),((10-N6)/10*9+1)))/9*7+Q6*0.3,1)) -> 5.2 | G6: {=_xlfn.IFS(F6="x", "x", F6<=2, 1, F6<=4, 2, F6<=6, 3, F6<=8, 4, F6<=10, 5)} -> 3 | H6: =IF(N6="x","x",IF(K6="x","x",(IF(G6=5,"Very High",IF(G6=4,"High",IF(G6=3,"Medium",IF(G6=2,"Low","Very Low"))))))) -> Medium | I6: =INDEX(Trends!$D$3:$D$404,MATCH(B6,Trends!$C$3:$C$404,0)) -> Increasing | J6: =VLOOKUP($B6,Reliability!$A$3:$I$300,9,FALSE) -> Very High | K6: =IF(OR(M6="x",L6="x"),"x",(10-GEOMEAN(((10-L6)/10*9+1),((10-M6)/10*9+1),((10-M6)/10*9+1)))/9*10) -> 4.9986878 | L6: =VLOOKUP($B6,'Impact of the crisis'!$C$6:$N$300,12,FALSE) -> 3.2005208 | M6: =VLOOKUP($B6,'Impact of the crisis'!$C$6:$AB$300,26,FALSE) -> 5.7381254 | N6: =VLOOKUP($B6,'Conditions of people affected'!$C$6:$R$300,16,FALSE) -> 4.9977618 | O6: =VLOOKUP($B6,'Conditions of people affected'!$C$6:$R$300,9,FALSE) -> 3.9955236 | P6: =VLOOKUP($B6,'Conditions of people affected'!$C$6:$R$300,15,FALSE) -> 6 | Q6: =IF(OR(S6="x",R6="x"),R6,(10-GEOMEAN(((10-R6)/10*9+1),((10-S6)/10*9+1)))/9*10) -> 5.7841694 | R6: =VLOOKUP($B6,'Complexity of the crisis'!$C$6:$AN$300,22,FALSE) -> 6.0539473 | S6: =VLOOKUP($B6,'Complexity of the crisis'!$C$6:$AN$300,38,FALSE) -> 5.5 | T6: =VLOOKUP(B6,Lists!$C$3:$E$300,3,FALSE) -> Africa | U6: =VLOOKUP(B6,'INFORM Severity - hidden'!$C$5:$V$300,20,FALSE) -> 46259
A7: {=IFERROR(INDEX(Lists!$B$2:$B$200,SMALL(IF(Lists!$H$2:$H$200="Yes",ROW(Lists!$B$2:$B$200)),ROW(3:3))-1,1),"")} -> Conflict in northern region of Benin | B7: =VLOOKUP(A7,Lists!$B$2:$G$200,2,FALSE) -> BEN002 | C7: =VLOOKUP(B7,'INFORM Severity - hidden'!$C$5:$D$200,2,FALSE) -> Benin | D7: =VLOOKUP(A7,Lists!$B$2:$G$200,3,FALSE) -> BEN | E7: =VLOOKUP(A7,Lists!$B$2:$G$200,5,FALSE) -> Conflict/ Violence | F7: =IF(OR(N7="x",K7="x"),"x",ROUND((10-GEOMEAN(((10-K7)/10*9+1),((10-N7)/10*9+1),((10-N7)/10*9+1)))/9*7+Q7*0.3,1)) -> 4.7 | G7: {=_xlfn.IFS(F7="x", "x", F7<=2, 1, F7<=4, 2, F7<=6, 3, F7<=8, 4, F7<=10, 5)} -> 3 | H7: =IF(N7="x","x",IF(K7="x","x",(IF(G7=5,"Very High",IF(G7=4,"High",IF(G7=3,"Medium",IF(G7=2,"Low","Very Low"))))))) -> Medium | I7: =INDEX(Trends!$D$3:$D$404,MATCH(B7,Trends!$C$3:$C$404,0)) -> Increasing | J7: =VLOOKUP($B7,Reliability!$A$3:$I$300,9,FALSE) -> High | K7: =IF(OR(M7="x",L7="x"),"x",(10-GEOMEAN(((10-L7)/10*9+1),((10-M7)/10*9+1),((10-M7)/10*9+1)))/9*10) -> 4.813692 | L7: =VLOOKUP($B7,'Impact of the crisis'!$C$6:$N$300,12,FALSE) -> 3.5816787 | M7: =VLOOKUP($B7,'Impact of the crisis'!$C$6:$AB$300,26,FALSE) -> 5.3519029 | N7: =VLOOKUP($B7,'Conditions of people affected'!$C$6:$R$300,16,FALSE) -> 4.6348791 | O7: =VLOOKUP($B7,'Conditions of people affected'!$C$6:$R$300,9,FALSE) -> 3.4039643 | P7: =VLOOKUP($B7,'Conditions of people affected'!$C$6:$R$300,15,FALSE) -> 5.8657938 | Q7: =IF(OR(S7="x",R7="x"),R7,(10-GEOMEAN(((10-R7)/10*9+1),((10-S7)/10*9+1)))/9*10) -> 4.5963951 | R7: =VLOOKUP($B7,'Complexity of the crisis'!$C$6:$AN$300,22,FALSE) -> 5.1427718 | S7: =VLOOKUP($B7,'Complexity of the crisis'!$C$6:$AN$300,38,FALSE) -> 4 | T7: =VLOOKUP(B7,Lists!$C$3:$E$300,3,FALSE) -> Africa | U7: =VLOOKUP(B7,'INFORM Severity - hidden'!$C$5:$V$300,20,FALSE) -> 46260
A8: {=IFERROR(INDEX(Lists!$B$2:$B$200,SMALL(IF(Lists!$H$2:$H$200="Yes",ROW(Lists!$B$2:$B$200)),ROW(4:4))-1,1),"")} -> Conflict and Climatic Shocks in Burkina Faso | B8: =VLOOKUP(A8,Lists!$B$2:$G$200,2,FALSE) -> BFA002 | C8: =VLOOKUP(B8,'INFORM Severity - hidden'!$C$5:$D$200,2,FALSE) -> Burkina Faso | D8: =VLOOKUP(A8,Lists!$B$2:$G$200,3,FALSE) -> BFA | E8: =VLOOKUP(A8,Lists!$B$2:$G$200,5,FALSE) -> Conflict/ Violence,Drought/drier conditions,Floods | F8: =IF(OR(N8="x",K8="x"),"x",ROUND((10-GEOMEAN(((10-K8)/10*9+1),((10-N8)/10*9+1),((10-N8)/10*9+1)))/9*7+Q8*0.3,1)) -> 8.4 | G8: {=_xlfn.IFS(F8="x", "x", F8<=2, 1, F8<=4, 2, F8<=6, 3, F8<=8, 4, F8<=10, 5)} -> 5 | H8: =IF(N8="x","x",IF(K8="x","x",(IF(G8=5,"Very High",IF(G8=4,"High",IF(G8=3,"Medium",IF(G8=2,"Low","Very Low"))))))) -> Very High | I8: =INDEX(Trends!$D$3:$D$404,MATCH(B8,Trends!$C$3:$C$404,0)) -> Stable | J8: =VLOOKUP($B8,Reliability!$A$3:$I$300,9,FALSE) -> High | K8: =IF(OR(M8="x",L8="x"),"x",(10-GEOMEAN(((10-L8)/10*9+1),((10-M8)/10*9+1),((10-M8)/10*9+1)))/9*10) -> 8.6112931 | L8: =VLOOKUP($B8,'Impact of the crisis'!$C$6:$N$300,12,FALSE) -> 9.3542845 | M8: =VLOOKUP($B8,'Impact of the crisis'!$C$6:$AB$300,26,FALSE) -> 8.1291763 | N8: =VLOOKUP($B8,'Conditions of people affected'!$C$6:$R$300,16,FALSE) -> 8.4111629 | O8: =VLOOKUP($B8,'Conditions of people affected'!$C$6:$R$300,9,FALSE) -> 8.8223258 | P8: =VLOOKUP($B8,'Conditions of people affected'!$C$6:$R$300,15,FALSE) -> 8 | Q8: =IF(OR(S8="x",R8="x"),R8,(10-GEOMEAN(((10-R8)/10*9+1),((10-S8)/10*9+1)))/9*10) -> 8.0905786 | R8: =VLOOKUP($B8,'Complexity of the crisis'!$C$6:$AN$300,22,FALSE) -> 6.7893978 | S8: =VLOOKUP($B8,'Complexity of the crisis'!$C$6:$AN$300,38,FALSE) -> 9 | T8: =VLOOKUP(B8,Lists!$C$3:$E$300,3,FALSE) -> Africa | U8: =VLOOKUP(B8,'INFORM Severity - hidden'!$C$5:$V$300,20,FALSE) -> 46260
A9: {=IFERROR(INDEX(Lists!$B$2:$B$200,SMALL(IF(Lists!$H$2:$H$200="Yes",ROW(Lists!$B$2:$B$200)),ROW(5:5))-1,1),"")} -> Multiple crises in Bangladesh | B9: =VLOOKUP(A9,Lists!$B$2:$G$200,2,FALSE) -> BGD001 | C9: =VLOOKUP(B9,'INFORM Severity - hidden'!$C$5:$D$200,2,FALSE) -> Bangladesh | D9: =VLOOKUP(A9,Lists!$B$2:$G$200,3,FALSE) -> BGD | E9: =VLOOKUP(A9,Lists!$B$2:$G$200,5,FALSE) -> International Displacement,Floods,Cyclone,Political/economic crisis | F9: =IF(OR(N9="x",K9="x"),"x",ROUND((10-GEOMEAN(((10-K9)/10*9+1),((10-N9)/10*9+1),((10-N9)/10*9+1)))/9*7+Q9*0.3,1)) -> 6.9 | G9: {=_xlfn.IFS(F9="x", "x", F9<=2, 1, F9<=4, 2, F9<=6, 3, F9<=8, 4, F9<=10, 5)} -> 4 | H9: =IF(N9="x","x",IF(K9="x","x",(IF(G9=5,"Very High",IF(G9=4,"High",IF(G9=3,"Medium",IF(G9=2,"Low","Very Low"))))))) -> High | I9: =INDEX(Trends!$D$3:$D$404,MATCH(B9,Trends!$C$3:$C$404,0)) -> Increasing | J9: =VLOOKUP($B9,Reliability!$A$3:$I$300,9,FALSE) -> Very High | K9: =IF(OR(M9="x",L9="x"),"x",(10-GEOMEAN(((10-L9)/10*9+1),((10-M9)/10*9+1),((10-M9)/10*9+1)))/9*10) -> 6.4191677 | L9: =VLOOKUP($B9,'Impact of the crisis'!$C$6:$N$300,12,FALSE) -> 7.3165956 | M9: =VLOOKUP($B9,'Impact of the crisis'!$C$6:$AB$300,26,FALSE) -> 5.893749 | N9: =VLOOKUP($B9,'Conditions of people affected'!$C$6:$R$300,16,FALSE) -> 8.0974046 | O9: =VLOOKUP($B9,'Conditions of people affected'!$C$6:$R$300,9,FALSE) -> 10 | P9: =VLOOKUP($B9,'Conditions of people affected'!$C$6:$R$300,15,FALSE) -> 6.1948091 | Q9: =IF(OR(S9="x",R9="x"),R9,(10-GEOMEAN(((10-R9)/10*9+1),((10-S9)/10*9+1)))/9*10) -> 5.098465 | R9: =VLOOKUP($B9,'Complexity of the crisis'!$C$6:$AN$300,22,FALSE) -> 4.668196 | S9: =VLOOKUP($B9,'Complexity of the crisis'!$C$6:$AN$300,38,FALSE) -> 5.5 | T9: =VLOOKUP(B9,Lists!$C$3:$E$300,3,FALSE) -> Asia | U9: =VLOOKUP(B9,'INFORM Severity - hidden'!$C$5:$V$300,20,FALSE) -> 46265
A10: {=IFERROR(INDEX(Lists!$B$2:$B$200,SMALL(IF(Lists!$H$2:$H$200="Yes",ROW(Lists!$B$2:$B$200)),ROW(6:6))-1,1),"")} -> Displacement from Venezuela to Brazil | B10: =VLOOKUP(A10,Lists!$B$2:$G$200,2,FALSE) -> BRA002 | C10: =VLOOKUP(B10,'INFORM Severity - hidden'!$C$5:$D$200,2,FALSE) -> Brazil | D10: =VLOOKUP(A10,Lists!$B$2:$G$200,3,FALSE) -> BRA | E10: =VLOOKUP(A10,Lists!$B$2:$G$200,5,FALSE) -> International Displacement | F10: =IF(OR(N10="x",K10="x"),"x",ROUND((10-GEOMEAN(((10-K10)/10*9+1),((10-N10)/10*9+1),((10-N10)/10*9+1)))/9*7+Q10*0.3,1)) -> 5.2 | G10: {=_xlfn.IFS(F10="x", "x", F10<=2, 1, F10<=4, 2, F10<=6, 3, F10<=8, 4, F10<=10, 5)} -> 3 | H10: =IF(N10="x","x",IF(K10="x","x",(IF(G10=5,"Very High",IF(G10=4,"High",IF(G10=3,"Medium",IF(G10=2,"Low","Very Low"))))))) -> Medium | I10: =INDEX(Trends!$D$3:$D$404,MATCH(B10,Trends!$C$3:$C$404,0)) -> Decreasing | J10: =VLOOKUP($B10,Reliability!$A$3:$I$300,9,FALSE) -> Medium | K10: =IF(OR(M10="x",L10="x"),"x",(10-GEOMEAN(((10-L10)/10*9+1),((10-M10)/10*9+1),((10-M10)/10*9+1)))/9*10) -> 7.4869034 | L10: =VLOOKUP($B10,'Impact of the crisis'!$C$6:$N$300,12,FALSE) -> 8.1391472 | M10: =VLOOKUP($B10,'Impact of the crisis'!$C$6:$AB$300,26,FALSE) -> 7.1089197 | N10: =VLOOKUP($B10,'Conditions of people affected'!$C$6:$R$300,16,FALSE) -> 4.1683117 | O10: =VLOOKUP($B10,'Conditions of people affected'!$C$6:$R$300,9,FALSE) -> 5.8272934 | P10: =VLOOKUP($B10,'Conditions of people affected'!$C$6:$R$300,15,FALSE) -> 2.5093299 | Q10: =IF(OR(S10="x",R10="x"),R10,(10-GEOMEAN(((10-R10)/10*9+1),((10-S10)/10*9+1)))/9*10) -> 4.5067709 | R10: =VLOOKUP($B10,'Complexity of the crisis'!$C$6:$AN$300,22,FALSE) -> 4.9774269 | S10: =VLOOKUP($B10,'Complexity of the crisis'!$C$6:$AN$300,38,FALSE) -> 4 | T10: =VLOOKUP(B10,Lists!$C$3:$E$300,3,FALSE) -> Americas | U10: =VLOOKUP(B10,'INFORM Severity - hidden'!$C$5:$V$300,20,FALSE) -> 46265
A11: {=IFERROR(INDEX(Lists!$B$2:$B$200,SMALL(IF(Lists!$H$2:$H$200="Yes",ROW(Lists!$B$2:$B$200)),ROW(7:7))-1,1),"")} -> Conflict and Climatic Shocks in CAR | B11: =VLOOKUP(A11,Lists!$B$2:$G$200,2,FALSE) -> CAF001 | C11: =VLOOKUP(B11,'INFORM Severity - hidden'!$C$5:$D$200,2,FALSE) -> Central African Republic | D11: =VLOOKUP(A11,Lists!$B$2:$G$200,3,FALSE) -> CAF | E11: =VLOOKUP(A11,Lists!$B$2:$G$200,5,FALSE) -> Conflict/ Violence,Floods | F11: =IF(OR(N11="x",K11="x"),"x",ROUND((10-GEOMEAN(((10-K11)/10*9+1),((10-N11)/10*9+1),((10-N11)/10*9+1)))/9*7+Q11*0.3,1)) -> 8 | G11: {=_xlfn.IFS(F11="x", "x", F11<=2, 1, F11<=4, 2, F11<=6, 3, F11<=8, 4, F11<=10, 5)} -> 4 | H11: =IF(N11="x","x",IF(K11="x","x",(IF(G11=5,"Very High",IF(G11=4,"High",IF(G11=3,"Medium",IF(G11=2,"Low","Very Low"))))))) -> High | I11: =INDEX(Trends!$D$3:$D$404,MATCH(B11,Trends!$C$3:$C$404,0)) -> Stable | J11: =VLOOKUP($B11,Reliability!$A$3:$I$300,9,FALSE) -> High | K11: =IF(OR(M11="x",L11="x"),"x",(10-GEOMEAN(((10-L11)/10*9+1),((10-M11)/10*9+1),((10-M11)/10*9+1)))/9*10) -> 8.5901502 | L11: =VLOOKUP($B11,'Impact of the crisis'!$C$6:$N$300,12,FALSE) -> 8.8042929 | M11: =VLOOKUP($B11,'Impact of the crisis'!$C$6:$AB$300,26,FALSE) -> 8.4757358 | N11: =VLOOKUP($B11,'Conditions of people affected'!$C$6:$R$300,16,FALSE) -> 7.8692477 | O11: =VLOOKUP($B11,'Conditions of people affected'!$C$6:$R$300,9,FALSE) -> 7.8172587 | P11: =VLOOKUP($B11,'Conditions of people affected'!$C$6:$R$300,15,FALSE) -> 7.9212367 | Q11: =IF(OR(S11="x",R11="x"),R11,(10-GEOMEAN(((10-R11)/10*9+1),((10-S11)/10*9+1)))/9*10) -> 7.7320969 | R11: =VLOOKUP($B11,'Complexity of the crisis'!$C$6:$AN$300,22,FALSE) -> 6.7383606 | S11: =VLOOKUP($B11,'Complexity of the crisis'!$C$6:$AN$300,38,FALSE) -> 8.5 | T11: =VLOOKUP(B11,Lists!$C$3:$E$300,3,FALSE) -> Africa | U11: =VLOOKUP(B11,'INFORM Severity - hidden'!$C$5:$V$300,20,FALSE) -> 46265
A12: {=IFERROR(INDEX(Lists!$B$2:$B$200,SMALL(IF(Lists!$H$2:$H$200="Yes",ROW(Lists!$B$2:$B$200)),ROW(8:8))-1,1),"")} -> Displacement from Venezuela to Chile | B12: =VLOOKUP(A12,Lists!$B$2:$G$200,2,FALSE) -> CHL002 | C12: =VLOOKUP(B12,'INFORM Severity - hidden'!$C$5:$D$200,2,FALSE) -> Chile | D12: =VLOOKUP(A12,Lists!$B$2:$G$200,3,FALSE) -> CHL | E12: =VLOOKUP(A12,Lists!$B$2:$G$200,5,FALSE) -> International Displacement | F12: =IF(OR(N12="x",K12="x"),"x",ROUND((10-GEOMEAN(((10-K12)/10*9+1),((10-N12)/10*9+1),((10-N12)/10*9+1)))/9*7+Q12*0.3,1)) -> 5 | G12: {=_xlfn.IFS(F12="x", "x", F12<=2, 1, F12<=4, 2, F12<=6, 3, F12<=8, 4, F12<=10, 5)} -> 3 | H12: =IF(N12="x","x",IF(K12="x","x",(IF(G12=5,"Very High",IF(G12=4,"High",IF(G12=3,"Medium",IF(G12=2,"Low","Very Low"))))))) -> Medium | I12: =INDEX(Trends!$D$3:$D$404,MATCH(B12,Trends!$C$3:$C$404,0)) -> Stable | J12: =VLOOKUP($B12,Reliability!$A$3:$I$300,9,FALSE) -> Very High | K12: =IF(OR(M12="x",L12="x"),"x",(10-GEOMEAN(((10-L12)/10*9+1),((10-M12)/10*9+1),((10-M12)/10*9+1)))/9*10) -> 5.8390041 | L12: =VLOOKUP($B12,'Impact of the crisis'!$C$6:$N$300,12,FALSE) -> 7.4345038 | M12: =VLOOKUP($B12,'Impact of the crisis'!$C$6:$AB$300,26,FALSE) -> 4.7978652 | N12: =VLOOKUP($B12,'Conditions of people affected'!$C$6:$R$300,16,FALSE) -> 5.6418975 | O12: =VLOOKUP($B12,'Conditions of people affected'!$C$6:$R$300,9,FALSE) -> 5.8730928 | P12: =VLOOKUP($B12,'Conditions of people affected'!$C$6:$R$300,15,FALSE) -> 5.4107023 | Q12: =IF(OR(S12="x",R12="x"),R12,(10-GEOMEAN(((10-R12)/10*9+1),((10-S12)/10*9+1)))/9*10) -> 3.3785691 | R12: =VLOOKUP($B12,'Complexity of the crisis'!$C$6:$AN$300,22,FALSE) -> 2.066912 | S12: =VLOOKUP($B12,'Complexity of the crisis'!$C$6:$AN$300,38,FALSE) -> 4.5 | T12: =VLOOKUP(B12,Lists!$C$3:$E$300,3,FALSE) -> Americas | U12: =VLOOKUP(B12,'INFORM Severity - hidden'!$C$5:$V$300,20,FALSE) -> 46265
A13: {=IFERROR(INDEX(Lists!$B$2:$B$200,SMALL(IF(Lists!$H$2:$H$200="Yes",ROW(Lists!$B$2:$B$200)),ROW(9:9))-1,1),"")} -> Displacement from Burkina Faso to northern Côte d’Ivoire | B13: =VLOOKUP(A13,Lists!$B$2:$G$200,2,FALSE) -> CIV002 | C13: =VLOOKUP(B13,'INFORM Severity - hidden'!$C$5:$D$200,2,FALSE) -> Ivory Coast | D13: =VLOOKUP(A13,Lists!$B$2:$G$200,3,FALSE) -> CIV | E13: =VLOOKUP(A13,Lists!$B$2:$G$200,5,FALSE) -> International Displacement | F13: =IF(OR(N13="x",K13="x"),"x",ROUND((10-GEOMEAN(((10-K13)/10*9+1),((10-N13)/10*9+1),((10-N13)/10*9+1)))/9*7+Q13*0.3,1)) -> 4.4 | G13: {=_xlfn.IFS(F13="x", "x", F13<=2, 1, F13<=4, 2, F13<=6, 3, F13<=8, 4, F13<=10, 5)} -> 3 | H13: =IF(N13="x","x",IF(K13="x","x",(IF(G13=5,"Very High",IF(G13=4,"High",IF(G13=3,"Medium",IF(G13=2,"Low","Very Low"))))))) -> Medium | I13: =INDEX(Trends!$D$3:$D$404,MATCH(B13,Trends!$C$3:$C$404,0)) -> Increasing | J13: =VLOOKUP($B13,Reliability!$A$3:$I$300,9,FALSE) -> Medium | K13: =IF(OR(M13="x",L13="x"),"x",(10-GEOMEAN(((10-L13)/10*9+1),((10-M13)/10*9+1),((10-M13)/10*9+1)))/9*10) -> 4.3647819 | L13: =VLOOKUP($B13,'Impact of the crisis'!$C$6:$N$300,12,FALSE) -> 1.276154 | M13: =VLOOKUP($B13,'Impact of the crisis'!$C$6:$AB$300,26,FALSE) -> 5.523643 | N13: =VLOOKUP($B13,'Conditions of people affected'!$C$6:$R$300,16,FALSE) -> 4.6141382 | O13: =VLOOKUP($B13,'Conditions of people affected'!$C$6:$R$300,9,FALSE) -> 3.2282765 | P13: =VLOOKUP($B13,'Conditions of people affected'!$C$6:$R$300,15,FALSE) -> 6 | Q13: =IF(OR(S13="x",R13="x"),R13,(10-GEOMEAN(((10-R13)/10*9+1),((10-S13)/10*9+1)))/9*10) -> 4.2104998 | R13: =VLOOKUP($B13,'Complexity of the crisis'!$C$6:$AN$300,22,FALSE) -> 5.240345 | S13: =VLOOKUP($B13,'Complexity of the crisis'!$C$6:$AN$300,38,FALSE) -> 3 | T13: =VLOOKUP(B13,Lists!$C$3:$E$300,3,FALSE) -> Africa | U13: =VLOOKUP(B13,'INFORM Severity - hidden'!$C$5:$V$300,20,FALSE) -> 46260
A14: {=IFERROR(INDEX(Lists!$B$2:$B$200,SMALL(IF(Lists!$H$2:$H$200="Yes",ROW(Lists!$B$2:$B$200)),ROW(10:10))-1,1),"")} -> Complex crisis in Cameroon | B14: =VLOOKUP(A14,Lists!$B$2:$G$200,2,FALSE) -> CMR005 | C14: =VLOOKUP(B14,'INFORM Severity - hidden'!$C$5:$D$200,2,FALSE) -> Cameroon | D14: =VLOOKUP(A14,Lists!$B$2:$G$200,3,FALSE) -> CMR | E14: =VLOOKUP(A14,Lists!$B$2:$G$200,5,FALSE) -> International Displacement,Conflict/ Violence,Floods | F14: =IF(OR(N14="x",K14="x"),"x",ROUND((10-GEOMEAN(((10-K14)/10*9+1),((10-N14)/10*9+1),((10-N14)/10*9+1)))/9*7+Q14*0.3,1)) -> 8.2 | G14: {=_xlfn.IFS(F14="x", "x", F14<=2, 1, F14<=4, 2, F14<=6, 3, F14<=8, 4, F14<=10, 5)} -> 5 | H14: =IF(N14="x","x",IF(K14="x","x",(IF(G14=5,"Very High",IF(G14=4,"High",IF(G14=3,"Medium",IF(G14=2,"Low","Very Low"))))))) -> Very High | I14: =INDEX(Trends!$D$3:$D$404,MATCH(B14,Trends!$C$3:$C$404,0)) -> Increasing | J14: =VLOOKUP($B14,Reliability!$A$3:$I$300,9,FALSE) -> High | K14: =IF(OR(M14="x",L14="x"),"x",(10-GEOMEAN(((10-L14)/10*9+1),((10-M14)/10*9+1),((10-M14)/10*9+1)))/9*10) -> 8.958582 | L14: =VLOOKUP($B14,'Impact of the crisis'!$C$6:$N$300,12,FALSE) -> 9.1230233 | M14: =VLOOKUP($B14,'Impact of the crisis'!$C$6:$AB$300,26,FALSE) -> 8.871329 | N14: =VLOOKUP($B14,'Conditions of people affected'!$C$6:$R$300,16,FALSE) -> 8.0982331 | O14: =VLOOKUP($B14,'Conditions of people affected'!$C$6:$R$300,9,FALSE) -> 8.1964662 | P14: =VLOOKUP($B14,'Conditions of people affected'!$C$6:$R$300,15,FALSE) -> 8 | Q14: =IF(OR(S14="x",R14="x"),R14,(10-GEOMEAN(((10-R14)/10*9+1),((10-S14)/10*9+1)))/9*10) -> 7.7441393 | R14: =VLOOKUP($B14,'Complexity of the crisis'!$C$6:$AN$300,22,FALSE) -> 6.7694732 | S14: =VLOOKUP($B14,'Complexity of the crisis'!$C$6:$AN$300,38,FALSE) -> 8.5 | T14: =VLOOKUP(B14,Lists!$C$3:$E$300,3,FALSE) -> Africa | U14: =VLOOKUP(B14,'INFORM Severity - hidden'!$C$5:$V$300,20,FALSE) -> 46260
A15: {=IFERROR(INDEX(Lists!$B$2:$B$200,SMALL(IF(Lists!$H$2:$H$200="Yes",ROW(Lists!$B$2:$B$200)),ROW(11:11))-1,1),"")} -> Complex crisis in DRC | B15: =VLOOKUP(A15,Lists!$B$2:$G$200,2,FALSE) -> COD001 | C15: =VLOOKUP(B15,'INFORM Severity - hidden'!$C$5:$D$200,2,FALSE) -> Democratic Republic of the Congo | D15: =VLOOKUP(A15,Lists!$B$2:$G$200,3,FALSE) -> COD | E15: =VLOOKUP(A15,Lists!$B$2:$G$200,5,FALSE) -> Conflict/ Violence,Floods | F15: =IF(OR(N15="x",K15="x"),"x",ROUND((10-GEOMEAN(((10-K15)/10*9+1),((10-N15)/10*9+1),((10-N15)/10*9+1)))/9*7+Q15*0.3,1)) -> 9.2 | G15: {=_xlfn.IFS(F15="x", "x", F15<=2, 1, F15<=4, 2, F15<=6, 3, F15<=8, 4, F15<=10, 5)} -> 5 | H15: =IF(N15="x","x",IF(K15="x","x",(IF(G15=5,"Very High",IF(G15=4,"High",IF(G15=3,"Medium",IF(G15=2,"Low","Very Low"))))))) -> Very High | I15: =INDEX(Trends!$D$3:$D$404,MATCH(B15,Trends!$C$3:$C$404,0)) -> Increasing | J15: =VLOOKUP($B15,Reliability!$A$3:$I$300,9,FALSE) -> Very High | K15: =IF(OR(M15="x",L15="x"),"x",(10-GEOMEAN(((10-L15)/10*9+1),((10-M15)/10*9+1),((10-M15)/10*9+1)))/9*10) -> 9.3968044 | L15: =VLOOKUP($B15,'Impact of the crisis'!$C$6:$N$300,12,FALSE) -> 10 | M15: =VLOOKUP($B15,'Impact of the crisis'!$C$6:$AB$300,26,FALSE) -> 8.9817269 | N15: =VLOOKUP($B15,'Conditions of people affected'!$C$6:$R$300,16,FALSE) -> 8.9870912 | O15: =VLOOKUP($B15,'Conditions of people affected'!$C$6:$R$300,9,FALSE) -> 10 | P15: =VLOOKUP($B15,'Conditions of people affected'!$C$6:$R$300,15,FALSE) -> 7.9741825 | Q15: =IF(OR(S15="x",R15="x"),R15,(10-GEOMEAN(((10-R15)/10*9+1),((10-S15)/10*9+1)))/9*10) -> 9.2177642 | R15: =VLOOKUP($B15,'Complexity of the crisis'!$C$6:$AN$300,22,FALSE) -> 7.8848249 | S15: =VLOOKUP($B15,'Complexity of the crisis'!$C$6:$AN$300,38,FALSE) -> 10 | T15: =VLOOKUP(B15,Lists!$C$3:$E$300,3,FALSE) -> Africa | U15: =VLOOKUP(B15,'INFORM Severity - hidden'!$C$5:$V$300,20,FALSE) -> 46260
A16: {=IFERROR(INDEX(Lists!$B$2:$B$200,SMALL(IF(Lists!$H$2:$H$200="Yes",ROW(Lists!$B$2:$B$200)),ROW(12:12))-1,1),"")} -> Multiple Crises in Colombia | B16: =VLOOKUP(A16,Lists!$B$2:$G$200,2,FALSE) -> COL004 | C16: =VLOOKUP(B16,'INFORM Severity - hidden'!$C$5:$D$200,2,FALSE) -> Colombia | D16: =VLOOKUP(A16,Lists!$B$2:$G$200,3,FALSE) -> COL | E16: =VLOOKUP(A16,Lists!$B$2:$G$200,5,FALSE) -> Conflict/ Violence,Drought/drier conditions,International Displacement,Floods,Earthquake | F16: =IF(OR(N16="x",K16="x"),"x",ROUND((10-GEOMEAN(((10-K16)/10*9+1),((10-N16)/10*9+1),((10-N16)/10*9+1)))/9*7+Q16*0.3,1)) -> 8.5 | G16: {=_xlfn.IFS(F16="x", "x", F16<=2, 1, F16<=4, 2, F16<=6, 3, F16<=8, 4, F16<=10, 5)} -> 5 | H16: =IF(N16="x","x",IF(K16="x","x",(IF(G16=5,"Very High",IF(G16=4,"High",IF(G16=3,"Medium",IF(G16=2,"Low","Very Low"))))))) -> Very High | I16: =INDEX(Trends!$D$3:$D$404,MATCH(B16,Trends!$C$3:$C$404,0)) -> Increasing | J16: =VLOOKUP($B16,Reliability!$A$3:$I$300,9,FALSE) -> Very High | K16: =IF(OR(M16="x",L16="x"),"x",(10-GEOMEAN(((10-L16)/10*9+1),((10-M16)/10*9+1),((10-M16)/10*9+1)))/9*10) -> 9.3590518 | L16: =VLOOKUP($B16,'Impact of the crisis'!$C$6:$N$300,12,FALSE) -> 9.9864161 | M16: =VLOOKUP($B16,'Impact of the crisis'!$C$6:$AB$300,26,FALSE) -> 8.9243274 | N16: =VLOOKUP($B16,'Conditions of people affected'!$C$6:$R$300,16,FALSE) -> 9 | O16: =VLOOKUP($B16,'Conditions of people affected'!$C$6:$R$300,9,FALSE) -> 10 | P16: =VLOOKUP($B16,'Conditions of people affected'!$C$6:$R$300,15,FALSE) -> 8 | Q16: =IF(OR(S16="x",R16="x"),R16,(10-GEOMEAN(((10-R16)/10*9+1),((10-S16)/10*9+1)))/9*10) -> 7.0258804 | R16: =VLOOKUP($B16,'Complexity of the crisis'!$C$6:$AN$300,22,FALSE) -> 5.7467544 | S16: =VLOOKUP($B16,'Complexity of the crisis'!$C$6:$AN$300,38,FALSE) -> 8 | T16: =VLOOKUP(B16,Lists!$C$3:$E$300,3,FALSE) -> Americas | U16: =VLOOKUP(B16,'INFORM Severity - hidden'!$C$5:$V$300,20,FALSE) -> 46265
A17: {=IFERROR(INDEX(Lists!$B$2:$B$200,SMALL(IF(Lists!$H$2:$H$200="Yes",ROW(Lists!$B$2:$B$200)),ROW(13:13))-1,1),"")} -> Multiple Crises in Costa Rica | B17: =VLOOKUP(A17,Lists!$B$2:$G$200,2,FALSE) -> CRI001 | C17: =VLOOKUP(B17,'INFORM Severity - hidden'!$C$5:$D$200,2,FALSE) -> Costa Rica | D17: =VLOOKUP(A17,Lists!$B$2:$G$200,3,FALSE) -> CRI | E17: =VLOOKUP(A17,Lists!$B$2:$G$200,5,FALSE) -> International Displacement | F17: =IF(OR(N17="x",K17="x"),"x",ROUND((10-GEOMEAN(((10-K17)/10*9+1),((10-N17)/10*9+1),((10-N17)/10*9+1)))/9*7+Q17*0.3,1)) -> 4.6 | G17: {=_xlfn.IFS(F17="x", "x", F17<=2, 1, F17<=4, 2, F17<=6, 3, F17<=8, 4, F17<=10, 5)} -> 3 | H17: =IF(N17="x","x",IF(K17="x","x",(IF(G17=5,"Very High",IF(G17=4,"High",IF(G17=3,"Medium",IF(G17=2,"Low","Very Low"))))))) -> Medium | I17: =INDEX(Trends!$D$3:$D$404,MATCH(B17,Trends!$C$3:$C$404,0)) -> Decreasing | J17: =VLOOKUP($B17,Reliability!$A$3:$I$300,9,FALSE) -> High | K17: =IF(OR(M17="x",L17="x"),"x",(10-GEOMEAN(((10-L17)/10*9+1),((10-M17)/10*9+1),((10-M17)/10*9+1)))/9*10) -> 5.490196 | L17: =VLOOKUP($B17,'Impact of the crisis'!$C$6:$N$300,12,FALSE) -> 7.6235808 | M17: =VLOOKUP($B17,'Impact of the crisis'!$C$6:$AB$300,26,FALSE) -> 3.9751652 | N17: =VLOOKUP($B17,'Conditions of people affected'!$C$6:$R$300,16,FALSE) -> 5.2522239 | O17: =VLOOKUP($B17,'Conditions of people affected'!$C$6:$R$300,9,FALSE) -> 4.6246328 | P17: =VLOOKUP($B17,'Conditions of people affected'!$C$6:$R$300,15,FALSE) -> 5.8798151 | Q17: =IF(OR(S17="x",R17="x"),R17,(10-GEOMEAN(((10-R17)/10*9+1),((10-S17)/10*9+1)))/9*10) -> 2.9176471 | R17: =VLOOKUP($B17,'Complexity of the crisis'!$C$6:$AN$300,22,FALSE) -> 2.2907363 | S17: =VLOOKUP($B17,'Complexity of the crisis'!$C$6:$AN$300,38,FALSE) -> 3.5 | T17: =VLOOKUP(B17,Lists!$C$3:$E$300,3,FALSE) -> Americas | U17: =VLOOKUP(B17,'INFORM Severity - hidden'!$C$5:$V$300,20,FALSE) -> 46265
A18: {=IFERROR(INDEX(Lists!$B$2:$B$200,SMALL(IF(Lists!$H$2:$H$200="Yes",ROW(Lists!$B$2:$B$200)),ROW(14:14))-1,1),"")} -> Complex Crisis in Cuba | B18: =VLOOKUP(A18,Lists!$B$2:$G$200,2,FALSE) -> CUB004 | C18: =VLOOKUP(B18,'INFORM Severity - hidden'!$C$5:$D$200,2,FALSE) -> Cuba | D18: =VLOOKUP(A18,Lists!$B$2:$G$200,3,FALSE) -> CUB | E18: =VLOOKUP(A18,Lists!$B$2:$G$200,5,FALSE) -> Cyclone,Political/economic crisis | F18: =IF(OR(N18="x",K18="x"),"x",ROUND((10-GEOMEAN(((10-K18)/10*9+1),((10-N18)/10*9+1),((10-N18)/10*9+1)))/9*7+Q18*0.3,1)) -> 6.9 | G18: {=_xlfn.IFS(F18="x", "x", F18<=2, 1, F18<=4, 2, F18<=6, 3, F18<=8, 4, F18<=10, 5)} -> 4 | H18: =IF(N18="x","x",IF(K18="x","x",(IF(G18=5,"Very High",IF(G18=4,"High",IF(G18=3,"Medium",IF(G18=2,"Low","Very Low"))))))) -> High | I18: =INDEX(Trends!$D$3:$D$404,MATCH(B18,Trends!$C$3:$C$404,0)) -> Stable | J18: =VLOOKUP($B18,Reliability!$A$3:$I$300,9,FALSE) -> High | K18: =IF(OR(M18="x",L18="x"),"x",(10-GEOMEAN(((10-L18)/10*9+1),((10-M18)/10*9+1),((10-M18)/10*9+1)))/9*10) -> 8.5336029 | L18: =VLOOKUP($B18,'Impact of the crisis'!$C$6:$N$300,12,FALSE) -> 8.4353199 | M18: =VLOOKUP($B18,'Impact of the crisis'!$C$6:$AB$300,26,FALSE) -> 8.5813822 | N18: =VLOOKUP($B18,'Conditions of people affected'!$C$6:$R$300,16,FALSE) -> 7.3720822 | O18: =VLOOKUP($B18,'Conditions of people affected'!$C$6:$R$300,9,FALSE) -> 8.7441643 | P18: =VLOOKUP($B18,'Conditions of people affected'!$C$6:$R$300,15,FALSE) -> 6 | Q18: =IF(OR(S18="x",R18="x"),R18,(10-GEOMEAN(((10-R18)/10*9+1),((10-S18)/10*9+1)))/9*10) -> 4.8873511 | R18: =VLOOKUP($B18,'Complexity of the crisis'!$C$6:$AN$300,22,FALSE) -> 5.2520069 | S18: =VLOOKUP($B18,'Complexity of the crisis'!$C$6:$AN$300,38,FALSE) -> 4.5 | T18: =VLOOKUP(B18,Lists!$C$3:$E$300,3,FALSE) -> Americas | U18: =VLOOKUP(B18,'INFORM Severity - hidden'!$C$5:$V$300,20,FALSE) -> 46265
A19: {=IFERROR(INDEX(Lists!$B$2:$B$200,SMALL(IF(Lists!$H$2:$H$200="Yes",ROW(Lists!$B$2:$B$200)),ROW(15:15))-1,1),"")} -> Multiple crises in Djibouti | B19: =VLOOKUP(A19,Lists!$B$2:$G$200,2,FALSE) -> DJI001 | C19: =VLOOKUP(B19,'INFORM Severity - hidden'!$C$5:$D$200,2,FALSE) -> Djibouti | D19: =VLOOKUP(A19,Lists!$B$2:$G$200,3,FALSE) -> DJI | E19: =VLOOKUP(A19,Lists!$B$2:$G$200,5,FALSE) -> International Displacement,Drought/drier conditions | F19: =IF(OR(N19="x",K19="x"),"x",ROUND((10-GEOMEAN(((10-K19)/10*9+1),((10-N19)/10*9+1),((10-N19)/10*9+1)))/9*7+Q19*0.3,1)) -> 6.1 | G19: {=_xlfn.IFS(F19="x", "x", F19<=2, 1, F19<=4, 2, F19<=6, 3, F19<=8, 4, F19<=10, 5)} -> 4 | H19: =IF(N19="x","x",IF(K19="x","x",(IF(G19=5,"Very High",IF(G19=4,"High",IF(G19=3,"Medium",IF(G19=2,"Low","Very Low"))))))) -> High | I19: =INDEX(Trends!$D$3:$D$404,MATCH(B19,Trends!$C$3:$C$404,0)) -> Increasing | J19: =VLOOKUP($B19,Reliability!$A$3:$I$300,9,FALSE) -> High | K19: =IF(OR(M19="x",L19="x"),"x",(10-GEOMEAN(((10-L19)/10*9+1),((10-M19)/10*9+1),((10-M19)/10*9+1)))/9*10) -> 5.279075 | L19: =VLOOKUP($B19,'Impact of the crisis'!$C$6:$N$300,12,FALSE) -> 6.2034513 | M19: =VLOOKUP($B19,'Impact of the crisis'!$C$6:$AB$300,26,FALSE) -> 4.7535128 | N19: =VLOOKUP($B19,'Conditions of people affected'!$C$6:$R$300,16,FALSE) -> 5.9271225 | O19: =VLOOKUP($B19,'Conditions of people affected'!$C$6:$R$300,9,FALSE) -> 4.7712125 | P19: =VLOOKUP($B19,'Conditions of people affected'!$C$6:$R$300,15,FALSE) -> 7.0830325 | Q19: =IF(OR(S19="x",R19="x"),R19,(10-GEOMEAN(((10-R19)/10*9+1),((10-S19)/10*9+1)))/9*10) -> 7.0016261 | R19: =VLOOKUP($B19,'Complexity of the crisis'!$C$6:$AN$300,22,FALSE) -> 5.6828681 | S19: =VLOOKUP($B19,'Complexity of the crisis'!$C$6:$AN$300,38,FALSE) -> 8 | T19: =VLOOKUP(B19,Lists!$C$3:$E$300,3,FALSE) -> Africa | U19: =VLOOKUP(B19,'INFORM Severity - hidden'!$C$5:$V$300,20,FALSE) -> 46261
A20: {=IFERROR(INDEX(Lists!$B$2:$B$200,SMALL(IF(Lists!$H$2:$H$200="Yes",ROW(Lists!$B$2:$B$200)),ROW(16:16))-1,1),"")} -> Displacement from Venezuela to Dominican Republic | B20: =VLOOKUP(A20,Lists!$B$2:$G$200,2,FALSE) -> DOM002 | C20: =VLOOKUP(B20,'INFORM Severity - hidden'!$C$5:$D$200,2,FALSE) -> Dominican Republic | D20: =VLOOKUP(A20,Lists!$B$2:$G$200,3,FALSE) -> DOM | E20: =VLOOKUP(A20,Lists!$B$2:$G$200,5,FALSE) -> International Displacement | F20: =IF(OR(N20="x",K20="x"),"x",ROUND((10-GEOMEAN(((10-K20)/10*9+1),((10-N20)/10*9+1),((10-N20)/10*9+1)))/9*7+Q20*0.3,1)) -> 4.2 | G20: {=_xlfn.IFS(F20="x", "x", F20<=2, 1, F20<=4, 2, F20<=6, 3, F20<=8, 4, F20<=10, 5)} -> 3 | H20: =IF(N20="x","x",IF(K20="x","x",(IF(G20=5,"Very High",IF(G20=4,"High",IF(G20=3,"Medium",IF(G20=2,"Low","Very Low"))))))) -> Medium | I20: =INDEX(Trends!$D$3:$D$404,MATCH(B20,Trends!$C$3:$C$404,0)) -> Increasing | J20: =VLOOKUP($B20,Reliability!$A$3:$I$300,9,FALSE) -> Medium | K20: =IF(OR(M20="x",L20="x"),"x",(10-GEOMEAN(((10-L20)/10*9+1),((10-M20)/10*9+1),((10-M20)/10*9+1)))/9*10) -> 6.5361642 | L20: =VLOOKUP($B20,'Impact of the crisis'!$C$6:$N$300,12,FALSE) -> 8.1938731 | M20: =VLOOKUP($B20,'Impact of the crisis'!$C$6:$AB$300,26,FALSE) -> 5.381922 | N20: =VLOOKUP($B20,'Conditions of people affected'!$C$6:$R$300,16,FALSE) -> 2.7337141 | O20: =VLOOKUP($B20,'Conditions of people affected'!$C$6:$R$300,9,FALSE) -> 2.8169935 | P20: =VLOOKUP($B20,'Conditions of people affected'!$C$6:$R$300,15,FALSE) -> 2.6504348 | Q20: =IF(OR(S20="x",R20="x"),R20,(10-GEOMEAN(((10-R20)/10*9+1),((10-S20)/10*9+1)))/9*10) -> 4.0339066 | R20: =VLOOKUP($B20,'Complexity of the crisis'!$C$6:$AN$300,22,FALSE) -> 4.0676515 | S20: =VLOOKUP($B20,'Complexity of the crisis'!$C$6:$AN$300,38,FALSE) -> 4 | T20: =VLOOKUP(B20,Lists!$C$3:$E$300,3,FALSE) -> Americas | U20: =VLOOKUP(B20,'INFORM Severity - hidden'!$C$5:$V$300,20,FALSE) -> 46265
A21: {=IFERROR(INDEX(Lists!$B$2:$B$200,SMALL(IF(Lists!$H$2:$H$200="Yes",ROW(Lists!$B$2:$B$200)),ROW(17:17))-1,1),"")} -> Multiple crises in Algeria | B21: =VLOOKUP(A21,Lists!$B$2:$G$200,2,FALSE) -> DZA004 | C21: =VLOOKUP(B21,'INFORM Severity - hidden'!$C$5:$D$200,2,FALSE) -> Algeria | D21: =VLOOKUP(A21,Lists!$B$2:$G$200,3,FALSE) -> DZA | E21: =VLOOKUP(A21,Lists!$B$2:$G$200,5,FALSE) -> International Displacement | F21: =IF(OR(N21="x",K21="x"),"x",ROUND((10-GEOMEAN(((10-K21)/10*9+1),((10-N21)/10*9+1),((10-N21)/10*9+1)))/9*7+Q21*0.3,1)) -> 5.6 | G21: {=_xlfn.IFS(F21="x", "x", F21<=2, 1, F21<=4, 2, F21<=6, 3, F21<=8, 4, F21<=10, 5)} -> 3 | H21: =IF(N21="x","x",IF(K21="x","x",(IF(G21=5,"Very High",IF(G21=4,"High",IF(G21=3,"Medium",IF(G21=2,"Low","Very Low"))))))) -> Medium | I21: =INDEX(Trends!$D$3:$D$404,MATCH(B21,Trends!$C$3:$C$404,0)) -> Decreasing | J21: =VLOOKUP($B21,Reliability!$A$3:$I$300,9,FALSE) -> High | K21: =IF(OR(M21="x",L21="x"),"x",(10-GEOMEAN(((10-L21)/10*9+1),((10-M21)/10*9+1),((10-M21)/10*9+1)))/9*10) -> 8.2969877 | L21: =VLOOKUP($B21,'Impact of the crisis'!$C$6:$N$300,12,FALSE) -> 10 | M21: =VLOOKUP($B21,'Impact of the crisis'!$C$6:$AB$300,26,FALSE) -> 6.6325762 | N21: =VLOOKUP($B21,'Conditions of people affected'!$C$6:$R$300,16,FALSE) -> 4.1641069 | O21: =VLOOKUP($B21,'Conditions of people affected'!$C$6:$R$300,9,FALSE) -> 5.4945334 | P21: =VLOOKUP($B21,'Conditions of people affected'!$C$6:$R$300,15,FALSE) -> 2.8336804 | Q21: =IF(OR(S21="x",R21="x"),R21,(10-GEOMEAN(((10-R21)/10*9+1),((10-S21)/10*9+1)))/9*10) -> 4.777499 | R21: =VLOOKUP($B21,'Complexity of the crisis'!$C$6:$AN$300,22,FALSE) -> 5.8405741 | S21: =VLOOKUP($B21,'Complexity of the crisis'!$C$6:$AN$300,38,FALSE) -> 3.5 | T21: =VLOOKUP(B21,Lists!$C$3:$E$300,3,FALSE) -> Africa | U21: =VLOOKUP(B21,'INFORM Severity - hidden'!$C$5:$V$300,20,FALSE) -> 46265
A22: {=IFERROR(INDEX(Lists!$B$2:$B$200,SMALL(IF(Lists!$H$2:$H$200="Yes",ROW(Lists!$B$2:$B$200)),ROW(18:18))-1,1),"")} -> Multiple crises in Ecuador | B22: =VLOOKUP(A22,Lists!$B$2:$G$200,2,FALSE) -> ECU001 | C22: =VLOOKUP(B22,'INFORM Severity - hidden'!$C$5:$D$200,2,FALSE) -> Ecuador | D22: =VLOOKUP(A22,Lists!$B$2:$G$200,3,FALSE) -> ECU | E22: =VLOOKUP(A22,Lists!$B$2:$G$200,5,FALSE) -> International Displacement,Conflict/ Violence,Floods | F22: =IF(OR(N22="x",K22="x"),"x",ROUND((10-GEOMEAN(((10-K22)/10*9+1),((10-N22)/10*9+1),((10-N22)/10*9+1)))/9*7+Q22*0.3,1)) -> 7.4 | G22: {=_xlfn.IFS(F22="x", "x", F22<=2, 1, F22<=4, 2, F22<=6, 3, F22<=8, 4, F22<=10, 5)} -> 4 | H22: =IF(N22="x","x",IF(K22="x","x",(IF(G22=5,"Very High",IF(G22=4,"High",IF(G22=3,"Medium",IF(G22=2,"Low","Very Low"))))))) -> High | I22: =INDEX(Trends!$D$3:$D$404,MATCH(B22,Trends!$C$3:$C$404,0)) -> Increasing | J22: =VLOOKUP($B22,Reliability!$A$3:$I$300,9,FALSE) -> High | K22: =IF(OR(M22="x",L22="x"),"x",(10-GEOMEAN(((10-L22)/10*9+1),((10-M22)/10*9+1),((10-M22)/10*9+1)))/9*10) -> 8.5612832 | L22: =VLOOKUP($B22,'Impact of the crisis'!$C$6:$N$300,12,FALSE) -> 9.1190626 | M22: =VLOOKUP($B22,'Impact of the crisis'!$C$6:$AB$300,26,FALSE) -> 8.2263068 | N22: =VLOOKUP($B22,'Conditions of people affected'!$C$6:$R$300,16,FALSE) -> 7.2484018 | O22: =VLOOKUP($B22,'Conditions of people affected'!$C$6:$R$300,9,FALSE) -> 8.2904613 | P22: =VLOOKUP($B22,'Conditions of people affected'!$C$6:$R$300,15,FALSE) -> 6.2063423 | Q22: =IF(OR(S22="x",R22="x"),R22,(10-GEOMEAN(((10-R22)/10*9+1),((10-S22)/10*9+1)))/9*10) -> 6.6845122 | R22: =VLOOKUP($B22,'Complexity of the crisis'!$C$6:$AN$300,22,FALSE) -> 5.6848649 | S22: =VLOOKUP($B22,'Complexity of the crisis'!$C$6:$AN$300,38,FALSE) -> 7.5 | T22: =VLOOKUP(B22,Lists!$C$3:$E$300,3,FALSE) -> Americas | U22: =VLOOKUP(B22,'INFORM Severity - hidden'!$C$5:$V$300,20,FALSE) -> 46265
A23: {=IFERROR(INDEX(Lists!$B$2:$B$200,SMALL(IF(Lists!$H$2:$H$200="Yes",ROW(Lists!$B$2:$B$200)),ROW(19:19))-1,1),"")} -> International displacement to Egypt | B23: =VLOOKUP(A23,Lists!$B$2:$G$200,2,FALSE) -> EGY004 | C23: =VLOOKUP(B23,'INFORM Severity - hidden'!$C$5:$D$200,2,FALSE) -> Egypt | D23: =VLOOKUP(A23,Lists!$B$2:$G$200,3,FALSE) -> EGY | E23: =VLOOKUP(A23,Lists!$B$2:$G$200,5,FALSE) -> International Displacement | F23: =IF(OR(N23="x",K23="x"),"x",ROUND((10-GEOMEAN(((10-K23)/10*9+1),((10-N23)/10*9+1),((10-N23)/10*9+1)))/9*7+Q23*0.3,1)) -> 5.8 | G23: {=_xlfn.IFS(F23="x", "x", F23<=2, 1, F23<=4, 2, F23<=6, 3, F23<=8, 4, F23<=10, 5)} -> 3 | H23: =IF(N23="x","x",IF(K23="x","x",(IF(G23=5,"Very High",IF(G23=4,"High",IF(G23=3,"Medium",IF(G23=2,"Low","Very Low"))))))) -> Medium | I23: =INDEX(Trends!$D$3:$D$404,MATCH(B23,Trends!$C$3:$C$404,0)) -> Increasing | J23: =VLOOKUP($B23,Reliability!$A$3:$I$300,9,FALSE) -> Very High | K23: =IF(OR(M23="x",L23="x"),"x",(10-GEOMEAN(((10-L23)/10*9+1),((10-M23)/10*9+1),((10-M23)/10*9+1)))/9*10) -> 4.8092352 | L23: =VLOOKUP($B23,'Impact of the crisis'!$C$6:$N$300,12,FALSE) -> 4.12845 | M23: =VLOOKUP($B23,'Impact of the crisis'!$C$6:$AB$300,26,FALSE) -> 5.1243175 | N23: =VLOOKUP($B23,'Conditions of people affected'!$C$6:$R$300,16,FALSE) -> 6.6131797 | O23: =VLOOKUP($B23,'Conditions of people affected'!$C$6:$R$300,9,FALSE) -> 7.2263594 | P23: =VLOOKUP($B23,'Conditions of people affected'!$C$6:$R$300,15,FALSE) -> 6 | Q23: =IF(OR(S23="x",R23="x"),R23,(10-GEOMEAN(((10-R23)/10*9+1),((10-S23)/10*9+1)))/9*10) -> 5.0446392 | R23: =VLOOKUP($B23,'Complexity of the crisis'!$C$6:$AN$300,22,FALSE) -> 4.5523244 | S23: =VLOOKUP($B23,'Complexity of the crisis'!$C$6:$AN$300,38,FALSE) -> 5.5 | T23: =VLOOKUP(B23,Lists!$C$3:$E$300,3,FALSE) -> Africa | U23: =VLOOKUP(B23,'INFORM Severity - hidden'!$C$5:$V$300,20,FALSE) -> 46265
A24: {=IFERROR(INDEX(Lists!$B$2:$B$200,SMALL(IF(Lists!$H$2:$H$200="Yes",ROW(Lists!$B$2:$B$200)),ROW(20:20))-1,1),"")} -> Complex crisis in Eritrea | B24: =VLOOKUP(A24,Lists!$B$2:$G$200,2,FALSE) -> ERI001 | C24: =VLOOKUP(B24,'INFORM Severity - hidden'!$C$5:$D$200,2,FALSE) -> Eritrea | D24: =VLOOKUP(A24,Lists!$B$2:$G$200,3,FALSE) -> ERI | E24: =VLOOKUP(A24,Lists!$B$2:$G$200,5,FALSE) -> International Displacement,Political/economic crisis | F24: =IF(OR(N24="x",K24="x"),"x",ROUND((10-GEOMEAN(((10-K24)/10*9+1),((10-N24)/10*9+1),((10-N24)/10*9+1)))/9*7+Q24*0.3,1)) -> 6.5 | G24: {=_xlfn.IFS(F24="x", "x", F24<=2, 1, F24<=4, 2, F24<=6, 3, F24<=8, 4, F24<=10, 5)} -> 4 | H24: =IF(N24="x","x",IF(K24="x","x",(IF(G24=5,"Very High",IF(G24=4,"High",IF(G24=3,"Medium",IF(G24=2,"Low","Very Low"))))))) -> High | I24: =INDEX(Trends!$D$3:$D$404,MATCH(B24,Trends!$C$3:$C$404,0)) -> Increasing | J24: =VLOOKUP($B24,Reliability!$A$3:$I$300,9,FALSE) -> High | K24: =IF(OR(M24="x",L24="x"),"x",(10-GEOMEAN(((10-L24)/10*9+1),((10-M24)/10*9+1),((10-M24)/10*9+1)))/9*10) -> 7.4555568 | L24: =VLOOKUP($B24,'Impact of the crisis'!$C$6:$N$300,12,FALSE) -> 7.7607261 | M24: =VLOOKUP($B24,'Impact of the crisis'!$C$6:$AB$300,26,FALSE) -> 7.2927016 | N24: =VLOOKUP($B24,'Conditions of people affected'!$C$6:$R$300,16,FALSE) -> 6.4023211 | O24: =VLOOKUP($B24,'Conditions of people affected'!$C$6:$R$300,9,FALSE) -> 6.8046423 | P24: =VLOOKUP($B24,'Conditions of people affected'!$C$6:$R$300,15,FALSE) -> 6 | Q24: =IF(OR(S24="x",R24="x"),R24,(10-GEOMEAN(((10-R24)/10*9+1),((10-S24)/10*9+1)))/9*10) -> 5.9584983 | R24: =VLOOKUP($B24,'Complexity of the crisis'!$C$6:$AN$300,22,FALSE) -> 7.0952327 | S24: =VLOOKUP($B24,'Complexity of the crisis'!$C$6:$AN$300,38,FALSE) -> 4.5 | T24: =VLOOKUP(B24,Lists!$C$3:$E$300,3,FALSE) -> Africa | U24: =VLOOKUP(B24,'INFORM Severity - hidden'!$C$5:$V$300,20,FALSE) -> 46259
A25: {=IFERROR(INDEX(Lists!$B$2:$B$200,SMALL(IF(Lists!$H$2:$H$200="Yes",ROW(Lists!$B$2:$B$200)),ROW(21:21))-1,1),"")} -> International displacement to Spain | B25: =VLOOKUP(A25,Lists!$B$2:$G$200,2,FALSE) -> ESP002 | C25: =VLOOKUP(B25,'INFORM Severity - hidden'!$C$5:$D$200,2,FALSE) -> Spain | D25: =VLOOKUP(A25,Lists!$B$2:$G$200,3,FALSE) -> ESP | E25: =VLOOKUP(A25,Lists!$B$2:$G$200,5,FALSE) -> International Displacement | F25: =IF(OR(N25="x",K25="x"),"x",ROUND((10-GEOMEAN(((10-K25)/10*9+1),((10-N25)/10*9+1),((10-N25)/10*9+1)))/9*7+Q25*0.3,1)) -> 3.5 | G25: {=_xlfn.IFS(F25="x", "x", F25<=2, 1, F25<=4, 2, F25<=6, 3, F25<=8, 4, F25<=10, 5)} -> 2 | H25: =IF(N25="x","x",IF(K25="x","x",(IF(G25=5,"Very High",IF(G25=4,"High",IF(G25=3,"Medium",IF(G25=2,"Low","Very Low"))))))) -> Low | I25: =INDEX(Trends!$D$3:$D$404,MATCH(B25,Trends!$C$3:$C$404,0)) -> Increasing | J25: =VLOOKUP($B25,Reliability!$A$3:$I$300,9,FALSE) -> Very High | K25: =IF(OR(M25="x",L25="x"),"x",(10-GEOMEAN(((10-L25)/10*9+1),((10-M25)/10*9+1),((10-M25)/10*9+1)))/9*10) -> 5.2167062 | L25: =VLOOKUP($B25,'Impact of the crisis'!$C$6:$N$300,12,FALSE) -> 4.5608588 | M25: =VLOOKUP($B25,'Impact of the crisis'!$C$6:$AB$300,26,FALSE) -> 5.5195776 | N25: =VLOOKUP($B25,'Conditions of people affected'!$C$6:$R$300,16,FALSE) -> 2.804263 | O25: =VLOOKUP($B25,'Conditions of people affected'!$C$6:$R$300,9,FALSE) -> 3.0635936 | P25: =VLOOKUP($B25,'Conditions of people affected'!$C$6:$R$300,15,FALSE) -> 2.5449323 | Q25: =IF(OR(S25="x",R25="x"),R25,(10-GEOMEAN(((10-R25)/10*9+1),((10-S25)/10*9+1)))/9*10) -> 3.0376561 | R25: =VLOOKUP($B25,'Complexity of the crisis'!$C$6:$AN$300,22,FALSE) -> 3.5417424 | S25: =VLOOKUP($B25,'Complexity of the crisis'!$C$6:$AN$300,38,FALSE) -> 2.5 | T25: =VLOOKUP(B25,Lists!$C$3:$E$300,3,FALSE) -> Europe | U25: =VLOOKUP(B25,'INFORM Severity - hidden'!$C$5:$V$300,20,FALSE) -> 46265
A26: {=IFERROR(INDEX(Lists!$B$2:$B$200,SMALL(IF(Lists!$H$2:$H$200="Yes",ROW(Lists!$B$2:$B$200)),ROW(22:22))-1,1),"")} -> Multiple crises in Ethiopia | B26: =VLOOKUP(A26,Lists!$B$2:$G$200,2,FALSE) -> ETH001 | C26: =VLOOKUP(B26,'INFORM Severity - hidden'!$C$5:$D$200,2,FALSE) -> Ethiopia | D26: =VLOOKUP(A26,Lists!$B$2:$G$200,3,FALSE) -> ETH | E26: =VLOOKUP(A26,Lists!$B$2:$G$200,5,FALSE) -> International Displacement,Conflict/ Violence,Drought/drier conditions,Floods,Political/economic crisis | F26: =IF(OR(N26="x",K26="x"),"x",ROUND((10-GEOMEAN(((10-K26)/10*9+1),((10-N26)/10*9+1),((10-N26)/10*9+1)))/9*7+Q26*0.3,1)) -> 8.7 | G26: {=_xlfn.IFS(F26="x", "x", F26<=2, 1, F26<=4, 2, F26<=6, 3, F26<=8, 4, F26<=10, 5)} -> 5 | H26: =IF(N26="x","x",IF(K26="x","x",(IF(G26=5,"Very High",IF(G26=4,"High",IF(G26=3,"Medium",IF(G26=2,"Low","Very Low"))))))) -> Very High | I26: =INDEX(Trends!$D$3:$D$404,MATCH(B26,Trends!$C$3:$C$404,0)) -> Stable | J26: =VLOOKUP($B26,Reliability!$A$3:$I$300,9,FALSE) -> High | K26: =IF(OR(M26="x",L26="x"),"x",(10-GEOMEAN(((10-L26)/10*9+1),((10-M26)/10*9+1),((10-M26)/10*9+1)))/9*10) -> 9.3505732 | L26: =VLOOKUP($B26,'Impact of the crisis'!$C$6:$N$300,12,FALSE) -> 9.9999993 | M26: =VLOOKUP($B26,'Impact of the crisis'!$C$6:$AB$300,26,FALSE) -> 8.8950119 | N26: =VLOOKUP($B26,'Conditions of people affected'!$C$6:$R$300,16,FALSE) -> 8 | O26: =VLOOKUP($B26,'Conditions of people affected'!$C$6:$R$300,9,FALSE) -> 10 | P26: =VLOOKUP($B26,'Conditions of people affected'!$C$6:$R$300,15,FALSE) -> 6 | Q26: =IF(OR(S26="x",R26="x"),R26,(10-GEOMEAN(((10-R26)/10*9+1),((10-S26)/10*9+1)))/9*10) -> 8.9182704 | R26: =VLOOKUP($B26,'Complexity of the crisis'!$C$6:$AN$300,22,FALSE) -> 6.7834156 | S26: =VLOOKUP($B26,'Complexity of the crisis'!$C$6:$AN$300,38,FALSE) -> 10 | T26: =VLOOKUP(B26,Lists!$C$3:$E$300,3,FALSE) -> Africa | U26: =VLOOKUP(B26,'INFORM Severity - hidden'!$C$5:$V$300,20,FALSE) -> 46261
A27: {=IFERROR(INDEX(Lists!$B$2:$B$200,SMALL(IF(Lists!$H$2:$H$200="Yes",ROW(Lists!$B$2:$B$200)),ROW(23:23))-1,1),"")} -> International Displacement to Greece | B27: =VLOOKUP(A27,Lists!$B$2:$G$200,2,FALSE) -> GRC002 | C27: =VLOOKUP(B27,'INFORM Severity - hidden'!$C$5:$D$200,2,FALSE) -> Greece | D27: =VLOOKUP(A27,Lists!$B$2:$G$200,3,FALSE) -> GRC | E27: =VLOOKUP(A27,Lists!$B$2:$G$200,5,FALSE) -> International Displacement | F27: =IF(OR(N27="x",K27="x"),"x",ROUND((10-GEOMEAN(((10-K27)/10*9+1),((10-N27)/10*9+1),((10-N27)/10*9+1)))/9*7+Q27*0.3,1)) -> 4.3 | G27: {=_xlfn.IFS(F27="x", "x", F27<=2, 1, F27<=4, 2, F27<=6, 3, F27<=8, 4, F27<=10, 5)} -> 3 | H27: =IF(N27="x","x",IF(K27="x","x",(IF(G27=5,"Very High",IF(G27=4,"High",IF(G27=3,"Medium",IF(G27=2,"Low","Very Low"))))))) -> Medium | I27: =INDEX(Trends!$D$3:$D$404,MATCH(B27,Trends!$C$3:$C$404,0)) -> Stable | J27: =VLOOKUP($B27,Reliability!$A$3:$I$300,9,FALSE) -> Very High | K27: =IF(OR(M27="x",L27="x"),"x",(10-GEOMEAN(((10-L27)/10*9+1),((10-M27)/10*9+1),((10-M27)/10*9+1)))/9*10) -> 4.6791571 | L27: =VLOOKUP($B27,'Impact of the crisis'!$C$6:$N$300,12,FALSE) -> 1.8393178 | M27: =VLOOKUP($B27,'Impact of the crisis'!$C$6:$AB$300,26,FALSE) -> 5.7539769 | N27: =VLOOKUP($B27,'Conditions of people affected'!$C$6:$R$300,16,FALSE) -> 4.5823167 | O27: =VLOOKUP($B27,'Conditions of people affected'!$C$6:$R$300,9,FALSE) -> 3.1646334 | P27: =VLOOKUP($B27,'Conditions of people affected'!$C$6:$R$300,15,FALSE) -> 6 | Q27: =IF(OR(S27="x",R27="x"),R27,(10-GEOMEAN(((10-R27)/10*9+1),((10-S27)/10*9+1)))/9*10) -> 3.5576261 | R27: =VLOOKUP($B27,'Complexity of the crisis'!$C$6:$AN$300,22,FALSE) -> 3.6148159 | S27: =VLOOKUP($B27,'Complexity of the crisis'!$C$6:$AN$300,38,FALSE) -> 3.5 | T27: =VLOOKUP(B27,Lists!$C$3:$E$300,3,FALSE) -> Europe | U27: =VLOOKUP(B27,'INFORM Severity - hidden'!$C$5:$V$300,20,FALSE) -> 46265
A28: {=IFERROR(INDEX(Lists!$B$2:$B$200,SMALL(IF(Lists!$H$2:$H$200="Yes",ROW(Lists!$B$2:$B$200)),ROW(24:24))-1,1),"")} -> Climatic Shocks and Violence in Guatemala | B28: =VLOOKUP(A28,Lists!$B$2:$G$200,2,FALSE) -> GTM001 | C28: =VLOOKUP(B28,'INFORM Severity - hidden'!$C$5:$D$200,2,FALSE) -> Guatemala | D28: =VLOOKUP(A28,Lists!$B$2:$G$200,3,FALSE) -> GTM | E28: =VLOOKUP(A28,Lists!$B$2:$G$200,5,FALSE) -> Conflict/ Violence,Drought/drier conditions | F28: =IF(OR(N28="x",K28="x"),"x",ROUND((10-GEOMEAN(((10-K28)/10*9+1),((10-N28)/10*9+1),((10-N28)/10*9+1)))/9*7+Q28*0.3,1)) -> 7.4 | G28: {=_xlfn.IFS(F28="x", "x", F28<=2, 1, F28<=4, 2, F28<=6, 3, F28<=8, 4, F28<=10, 5)} -> 4 | H28: =IF(N28="x","x",IF(K28="x","x",(IF(G28=5,"Very High",IF(G28=4,"High",IF(G28=3,"Medium",IF(G28=2,"Low","Very Low"))))))) -> High | I28: =INDEX(Trends!$D$3:$D$404,MATCH(B28,Trends!$C$3:$C$404,0)) -> Increasing | J28: =VLOOKUP($B28,Reliability!$A$3:$I$300,9,FALSE) -> Very High | K28: =IF(OR(M28="x",L28="x"),"x",(10-GEOMEAN(((10-L28)/10*9+1),((10-M28)/10*9+1),((10-M28)/10*9+1)))/9*10) -> 8.2682274 | L28: =VLOOKUP($B28,'Impact of the crisis'!$C$6:$N$300,12,FALSE) -> 8.8375288 | M28: =VLOOKUP($B28,'Impact of the crisis'!$C$6:$AB$300,26,FALSE) -> 7.9321639 | N28: =VLOOKUP($B28,'Conditions of people affected'!$C$6:$R$300,16,FALSE) -> 7.3843869 | O28: =VLOOKUP($B28,'Conditions of people affected'!$C$6:$R$300,9,FALSE) -> 8.340513 | P28: =VLOOKUP($B28,'Conditions of people affected'!$C$6:$R$300,15,FALSE) -> 6.4282609 | Q28: =IF(OR(S28="x",R28="x"),R28,(10-GEOMEAN(((10-R28)/10*9+1),((10-S28)/10*9+1)))/9*10) -> 6.6192646 | R28: =VLOOKUP($B28,'Complexity of the crisis'!$C$6:$AN$300,22,FALSE) -> 6.2032687 | S28: =VLOOKUP($B28,'Complexity of the crisis'!$C$6:$AN$300,38,FALSE) -> 7 | T28: =VLOOKUP(B28,Lists!$C$3:$E$300,3,FALSE) -> Americas | U28: =VLOOKUP(B28,'INFORM Severity - hidden'!$C$5:$V$300,20,FALSE) -> 46265
A29: {=IFERROR(INDEX(Lists!$B$2:$B$200,SMALL(IF(Lists!$H$2:$H$200="Yes",ROW(Lists!$B$2:$B$200)),ROW(25:25))-1,1),"")} -> Climatic Shocks and Conflict and Violence in Honduras | B29: =VLOOKUP(A29,Lists!$B$2:$G$200,2,FALSE) -> HND001 | C29: =VLOOKUP(B29,'INFORM Severity - hidden'!$C$5:$D$200,2,FALSE) -> Honduras | D29: =VLOOKUP(A29,Lists!$B$2:$G$200,3,FALSE) -> HND | E29: =VLOOKUP(A29,Lists!$B$2:$G$200,5,FALSE) -> Drought/drier conditions,Conflict/ Violence | F29: =IF(OR(N29="x",K29="x"),"x",ROUND((10-GEOMEAN(((10-K29)/10*9+1),((10-N29)/10*9+1),((10-N29)/10*9+1)))/9*7+Q29*0.3,1)) -> 6.8 | G29: {=_xlfn.IFS(F29="x", "x", F29<=2, 1, F29<=4, 2, F29<=6, 3, F29<=8, 4, F29<=10, 5)} -> 4 | H29: =IF(N29="x","x",IF(K29="x","x",(IF(G29=5,"Very High",IF(G29=4,"High",IF(G29=3,"Medium",IF(G29=2,"Low","Very Low"))))))) -> High | I29: =INDEX(Trends!$D$3:$D$404,MATCH(B29,Trends!$C$3:$C$404,0)) -> Stable | J29: =VLOOKUP($B29,Reliability!$A$3:$I$300,9,FALSE) -> High | K29: =IF(OR(M29="x",L29="x"),"x",(10-GEOMEAN(((10-L29)/10*9+1),((10-M29)/10*9+1),((10-M29)/10*9+1)))/9*10) -> 7.6066855 | L29: =VLOOKUP($B29,'Impact of the crisis'!$C$6:$N$300,12,FALSE) -> 8.4297412 | M29: =VLOOKUP($B29,'Impact of the crisis'!$C$6:$AB$300,26,FALSE) -> 7.1047794 | N29: =VLOOKUP($B29,'Conditions of people affected'!$C$6:$R$300,16,FALSE) -> 6.9391233 | O29: =VLOOKUP($B29,'Conditions of people affected'!$C$6:$R$300,9,FALSE) -> 7.5263948 | P29: =VLOOKUP($B29,'Conditions of people affected'!$C$6:$R$300,15,FALSE) -> 6.3518519 | Q29: =IF(OR(S29="x",R29="x"),R29,(10-GEOMEAN(((10-R29)/10*9+1),((10-S29)/10*9+1)))/9*10) -> 6.0108704 | R29: =VLOOKUP($B29,'Complexity of the crisis'!$C$6:$AN$300,22,FALSE) -> 5.4698557 | S29: =VLOOKUP($B29,'Complexity of the crisis'!$C$6:$AN$300,38,FALSE) -> 6.5 | T29: =VLOOKUP(B29,Lists!$C$3:$E$300,3,FALSE) -> Americas | U29: =VLOOKUP(B29,'INFORM Severity - hidden'!$C$5:$V$300,20,FALSE) -> 46265
A30: {=IFERROR(INDEX(Lists!$B$2:$B$200,SMALL(IF(Lists!$H$2:$H$200="Yes",ROW(Lists!$B$2:$B$200)),ROW(26:26))-1,1),"")} -> Complex crisis in Haiti | B30: =VLOOKUP(A30,Lists!$B$2:$G$200,2,FALSE) -> HTI001 | C30: =VLOOKUP(B30,'INFORM Severity - hidden'!$C$5:$D$200,2,FALSE) -> Haiti | D30: =VLOOKUP(A30,Lists!$B$2:$G$200,3,FALSE) -> HTI | E30: =VLOOKUP(A30,Lists!$B$2:$G$200,5,FALSE) -> Conflict/ Violence,Political/economic crisis,Floods,Drought/drier conditions,Cyclone | F30: =IF(OR(N30="x",K30="x"),"x",ROUND((10-GEOMEAN(((10-K30)/10*9+1),((10-N30)/10*9+1),((10-N30)/10*9+1)))/9*7+Q30*0.3,1)) -> 8.9 | G30: {=_xlfn.IFS(F30="x", "x", F30<=2, 1, F30<=4, 2, F30<=6, 3, F30<=8, 4, F30<=10, 5)} -> 5 | H30: =IF(N30="x","x",IF(K30="x","x",(IF(G30=5,"Very High",IF(G30=4,"High",IF(G30=3,"Medium",IF(G30=2,"Low","Very Low"))))))) -> Very High | I30: =INDEX(Trends!$D$3:$D$404,MATCH(B30,Trends!$C$3:$C$404,0)) -> Increasing | J30: =VLOOKUP($B30,Reliability!$A$3:$I$300,9,FALSE) -> Very High | K30: =IF(OR(M30="x",L30="x"),"x",(10-GEOMEAN(((10-L30)/10*9+1),((10-M30)/10*9+1),((10-M30)/10*9+1)))/9*10) -> 9.1043458 | L30: =VLOOKUP($B30,'Impact of the crisis'!$C$6:$N$300,12,FALSE) -> 8.0495882 | M30: =VLOOKUP($B30,'Impact of the crisis'!$C$6:$AB$300,26,FALSE) -> 9.4864001 | N30: =VLOOKUP($B30,'Conditions of people affected'!$C$6:$R$300,16,FALSE) -> 9.3995567 | O30: =VLOOKUP($B30,'Conditions of people affected'!$C$6:$R$300,9,FALSE) -> 9.3570965 | P30: =VLOOKUP($B30,'Conditions of people affected'!$C$6:$R$300,15,FALSE) -> 9.4420168 | Q30: =IF(OR(S30="x",R30="x"),R30,(10-GEOMEAN(((10-R30)/10*9+1),((10-S30)/10*9+1)))/9*10) -> 8.0715509 | R30: =VLOOKUP($B30,'Complexity of the crisis'!$C$6:$AN$300,22,FALSE) -> 6.7347776 | S30: =VLOOKUP($B30,'Complexity of the crisis'!$C$6:$AN$300,38,FALSE) -> 9 | T30: =VLOOKUP(B30,Lists!$C$3:$E$300,3,FALSE) -> Americas | U30: =VLOOKUP(B30,'INFORM Severity - hidden'!$C$5:$V$300,20,FALSE) -> 46265
A31: {=IFERROR(INDEX(Lists!$B$2:$B$200,SMALL(IF(Lists!$H$2:$H$200="Yes",ROW(Lists!$B$2:$B$200)),ROW(27:27))-1,1),"")} -> Conflict in Papua | B31: =VLOOKUP(A31,Lists!$B$2:$G$200,2,FALSE) -> IDN002 | C31: =VLOOKUP(B31,'INFORM Severity - hidden'!$C$5:$D$200,2,FALSE) -> Indonesia | D31: =VLOOKUP(A31,Lists!$B$2:$G$200,3,FALSE) -> IDN | E31: =VLOOKUP(A31,Lists!$B$2:$G$200,5,FALSE) -> Conflict/ Violence | F31: =IF(OR(N31="x",K31="x"),"x",ROUND((10-GEOMEAN(((10-K31)/10*9+1),((10-N31)/10*9+1),((10-N31)/10*9+1)))/9*7+Q31*0.3,1)) -> 5.4 | G31: {=_xlfn.IFS(F31="x", "x", F31<=2, 1, F31<=4, 2, F31<=6, 3, F31<=8, 4, F31<=10, 5)} -> 3 | H31: =IF(N31="x","x",IF(K31="x","x",(IF(G31=5,"Very High",IF(G31=4,"High",IF(G31=3,"Medium",IF(G31=2,"Low","Very Low"))))))) -> Medium | I31: =INDEX(Trends!$D$3:$D$404,MATCH(B31,Trends!$C$3:$C$404,0)) -> Increasing | J31: =VLOOKUP($B31,Reliability!$A$3:$I$300,9,FALSE) -> Very High | K31: =IF(OR(M31="x",L31="x"),"x",(10-GEOMEAN(((10-L31)/10*9+1),((10-M31)/10*9+1),((10-M31)/10*9+1)))/9*10) -> 6.2623586 | L31: =VLOOKUP($B31,'Impact of the crisis'!$C$6:$N$300,12,FALSE) -> 4.1287356 | M31: =VLOOKUP($B31,'Impact of the crisis'!$C$6:$AB$300,26,FALSE) -> 7.0705338 | N31: =VLOOKUP($B31,'Conditions of people affected'!$C$6:$R$300,16,FALSE) -> 4.2612144 | O31: =VLOOKUP($B31,'Conditions of people affected'!$C$6:$R$300,9,FALSE) -> 3.6679018 | P31: =VLOOKUP($B31,'Conditions of people affected'!$C$6:$R$300,15,FALSE) -> 4.854527 | Q31: =IF(OR(S31="x",R31="x"),R31,(10-GEOMEAN(((10-R31)/10*9+1),((10-S31)/10*9+1)))/9*10) -> 6.3771833 | R31: =VLOOKUP($B31,'Complexity of the crisis'!$C$6:$AN$300,22,FALSE) -> 4.9052448 | S31: =VLOOKUP($B31,'Complexity of the crisis'!$C$6:$AN$300,38,FALSE) -> 7.5 | T31: =VLOOKUP(B31,Lists!$C$3:$E$300,3,FALSE) -> Asia | U31: =VLOOKUP(B31,'INFORM Severity - hidden'!$C$5:$V$300,20,FALSE) -> 46265
A32: {=IFERROR(INDEX(Lists!$B$2:$B$200,SMALL(IF(Lists!$H$2:$H$200="Yes",ROW(Lists!$B$2:$B$200)),ROW(28:28))-1,1),"")} -> Multiple crises in Indonesia | B32: =VLOOKUP(A32,Lists!$B$2:$G$200,2,FALSE) -> IDN007 | C32: =VLOOKUP(B32,'INFORM Severity - hidden'!$C$5:$D$200,2,FALSE) -> Indonesia | D32: =VLOOKUP(A32,Lists!$B$2:$G$200,3,FALSE) -> IDN | E32: =VLOOKUP(A32,Lists!$B$2:$G$200,5,FALSE) -> Conflict/ Violence,Floods,Cyclone | F32: =IF(OR(N32="x",K32="x"),"x",ROUND((10-GEOMEAN(((10-K32)/10*9+1),((10-N32)/10*9+1),((10-N32)/10*9+1)))/9*7+Q32*0.3,1)) -> 5.3 | G32: {=_xlfn.IFS(F32="x", "x", F32<=2, 1, F32<=4, 2, F32<=6, 3, F32<=8, 4, F32<=10, 5)} -> 3 | H32: =IF(N32="x","x",IF(K32="x","x",(IF(G32=5,"Very High",IF(G32=4,"High",IF(G32=3,"Medium",IF(G32=2,"Low","Very Low"))))))) -> Medium | I32: =INDEX(Trends!$D$3:$D$404,MATCH(B32,Trends!$C$3:$C$404,0)) -> Decreasing | J32: =VLOOKUP($B32,Reliability!$A$3:$I$300,9,FALSE) -> Very High | K32: =IF(OR(M32="x",L32="x"),"x",(10-GEOMEAN(((10-L32)/10*9+1),((10-M32)/10*9+1),((10-M32)/10*9+1)))/9*10) -> 5.7619228 | L32: =VLOOKUP($B32,'Impact of the crisis'!$C$6:$N$300,12,FALSE) -> 4.3497499 | M32: =VLOOKUP($B32,'Impact of the crisis'!$C$6:$AB$300,26,FALSE) -> 6.3532171 | N32: =VLOOKUP($B32,'Conditions of people affected'!$C$6:$R$300,16,FALSE) -> 4.252379 | O32: =VLOOKUP($B32,'Conditions of people affected'!$C$6:$R$300,9,FALSE) -> 3.799597 | P32: =VLOOKUP($B32,'Conditions of people affected'!$C$6:$R$300,15,FALSE) -> 4.705161 | Q32: =IF(OR(S32="x",R32="x"),R32,(10-GEOMEAN(((10-R32)/10*9+1),((10-S32)/10*9+1)))/9*10) -> 6.3771833 | R32: =VLOOKUP($B32,'Complexity of the crisis'!$C$6:$AN$300,22,FALSE) -> 4.9052448 | S32: =VLOOKUP($B32,'Complexity of the crisis'!$C$6:$AN$300,38,FALSE) -> 7.5 | T32: =VLOOKUP(B32,Lists!$C$3:$E$300,3,FALSE) -> Asia | U32: =VLOOKUP(B32,'INFORM Severity - hidden'!$C$5:$V$300,20,FALSE) -> 46265
A33: {=IFERROR(INDEX(Lists!$B$2:$B$200,SMALL(IF(Lists!$H$2:$H$200="Yes",ROW(Lists!$B$2:$B$200)),ROW(29:29))-1,1),"")} -> Multiple crises in Iran | B33: =VLOOKUP(A33,Lists!$B$2:$G$200,2,FALSE) -> IRN001 | C33: =VLOOKUP(B33,'INFORM Severity - hidden'!$C$5:$D$200,2,FALSE) -> Iran | D33: =VLOOKUP(A33,Lists!$B$2:$G$200,3,FALSE) -> IRN | E33: =VLOOKUP(A33,Lists!$B$2:$G$200,5,FALSE) -> Conflict/ Violence,International Displacement,Political/economic crisis | F33: =IF(OR(N33="x",K33="x"),"x",ROUND((10-GEOMEAN(((10-K33)/10*9+1),((10-N33)/10*9+1),((10-N33)/10*9+1)))/9*7+Q33*0.3,1)) -> 8.6 | G33: {=_xlfn.IFS(F33="x", "x", F33<=2, 1, F33<=4, 2, F33<=6, 3, F33<=8, 4, F33<=10, 5)} -> 5 | H33: =IF(N33="x","x",IF(K33="x","x",(IF(G33=5,"Very High",IF(G33=4,"High",IF(G33=3,"Medium",IF(G33=2,"Low","Very Low"))))))) -> Very High | I33: =INDEX(Trends!$D$3:$D$404,MATCH(B33,Trends!$C$3:$C$404,0)) -> Increasing | J33: =VLOOKUP($B33,Reliability!$A$3:$I$300,9,FALSE) -> High | K33: =IF(OR(M33="x",L33="x"),"x",(10-GEOMEAN(((10-L33)/10*9+1),((10-M33)/10*9+1),((10-M33)/10*9+1)))/9*10) -> 8.7909291 | L33: =VLOOKUP($B33,'Impact of the crisis'!$C$6:$N$300,12,FALSE) -> 9.7450274 | M33: =VLOOKUP($B33,'Impact of the crisis'!$C$6:$AB$300,26,FALSE) -> 8.0873712 | N33: =VLOOKUP($B33,'Conditions of people affected'!$C$6:$R$300,16,FALSE) -> 8.5112195 | O33: =VLOOKUP($B33,'Conditions of people affected'!$C$6:$R$300,9,FALSE) -> 10 | P33: =VLOOKUP($B33,'Conditions of people affected'!$C$6:$R$300,15,FALSE) -> 7.022439 | Q33: =IF(OR(S33="x",R33="x"),R33,(10-GEOMEAN(((10-R33)/10*9+1),((10-S33)/10*9+1)))/9*10) -> 8.6380806 | R33: =VLOOKUP($B33,'Complexity of the crisis'!$C$6:$AN$300,22,FALSE) -> 7.3150478 | S33: =VLOOKUP($B33,'Complexity of the crisis'!$C$6:$AN$300,38,FALSE) -> 9.5 | T33: =VLOOKUP(B33,Lists!$C$3:$E$300,3,FALSE) -> Middle east | U33: =VLOOKUP(B33,'INFORM Severity - hidden'!$C$5:$V$300,20,FALSE) -> 46265
A34: {=IFERROR(INDEX(Lists!$B$2:$B$200,SMALL(IF(Lists!$H$2:$H$200="Yes",ROW(Lists!$B$2:$B$200)),ROW(30:30))-1,1),"")} -> Internal displacement in Iraq | B34: =VLOOKUP(A34,Lists!$B$2:$G$200,2,FALSE) -> IRQ002 | C34: =VLOOKUP(B34,'INFORM Severity - hidden'!$C$5:$D$200,2,FALSE) -> Iraq | D34: =VLOOKUP(A34,Lists!$B$2:$G$200,3,FALSE) -> IRQ | E34: =VLOOKUP(A34,Lists!$B$2:$G$200,5,FALSE) -> Conflict/ Violence,Political/economic crisis | F34: =IF(OR(N34="x",K34="x"),"x",ROUND((10-GEOMEAN(((10-K34)/10*9+1),((10-N34)/10*9+1),((10-N34)/10*9+1)))/9*7+Q34*0.3,1)) -> 6.9 | G34: {=_xlfn.IFS(F34="x", "x", F34<=2, 1, F34<=4, 2, F34<=6, 3, F34<=8, 4, F34<=10, 5)} -> 4 | H34: =IF(N34="x","x",IF(K34="x","x",(IF(G34=5,"Very High",IF(G34=4,"High",IF(G34=3,"Medium",IF(G34=2,"Low","Very Low"))))))) -> High | I34: =INDEX(Trends!$D$3:$D$404,MATCH(B34,Trends!$C$3:$C$404,0)) -> Increasing | J34: =VLOOKUP($B34,Reliability!$A$3:$I$300,9,FALSE) -> High | K34: =IF(OR(M34="x",L34="x"),"x",(10-GEOMEAN(((10-L34)/10*9+1),((10-M34)/10*9+1),((10-M34)/10*9+1)))/9*10) -> 7.6730012 | L34: =VLOOKUP($B34,'Impact of the crisis'!$C$6:$N$300,12,FALSE) -> 9.3929738 | M34: =VLOOKUP($B34,'Impact of the crisis'!$C$6:$AB$300,26,FALSE) -> 6.2475911 | N34: =VLOOKUP($B34,'Conditions of people affected'!$C$6:$R$300,16,FALSE) -> 7.3614797 | O34: =VLOOKUP($B34,'Conditions of people affected'!$C$6:$R$300,9,FALSE) -> 8.1638991 | P34: =VLOOKUP($B34,'Conditions of people affected'!$C$6:$R$300,15,FALSE) -> 6.5590603 | Q34: =IF(OR(S34="x",R34="x"),R34,(10-GEOMEAN(((10-R34)/10*9+1),((10-S34)/10*9+1)))/9*10) -> 5.6476282 | R34: =VLOOKUP($B34,'Complexity of the crisis'!$C$6:$AN$300,22,FALSE) -> 4.6376941 | S34: =VLOOKUP($B34,'Complexity of the crisis'!$C$6:$AN$300,38,FALSE) -> 6.5 | T34: =VLOOKUP(B34,Lists!$C$3:$E$300,3,FALSE) -> Middle east | U34: =VLOOKUP(B34,'INFORM Severity - hidden'!$C$5:$V$300,20,FALSE) -> 46265
A35: {=IFERROR(INDEX(Lists!$B$2:$B$200,SMALL(IF(Lists!$H$2:$H$200="Yes",ROW(Lists!$B$2:$B$200)),ROW(31:31))-1,1),"")} -> International Displacement to Italy | B35: =VLOOKUP(A35,Lists!$B$2:$G$200,2,FALSE) -> ITA002 | C35: =VLOOKUP(B35,'INFORM Severity - hidden'!$C$5:$D$200,2,FALSE) -> Italy | D35: =VLOOKUP(A35,Lists!$B$2:$G$200,3,FALSE) -> ITA | E35: =VLOOKUP(A35,Lists!$B$2:$G$200,5,FALSE) -> International Displacement | F35: =IF(OR(N35="x",K35="x"),"x",ROUND((10-GEOMEAN(((10-K35)/10*9+1),((10-N35)/10*9+1),((10-N35)/10*9+1)))/9*7+Q35*0.3,1)) -> 3.9 | G35: {=_xlfn.IFS(F35="x", "x", F35<=2, 1, F35<=4, 2, F35<=6, 3, F35<=8, 4, F35<=10, 5)} -> 2 | H35: =IF(N35="x","x",IF(K35="x","x",(IF(G35=5,"Very High",IF(G35=4,"High",IF(G35=3,"Medium",IF(G35=2,"Low","Very Low"))))))) -> Low | I35: =INDEX(Trends!$D$3:$D$404,MATCH(B35,Trends!$C$3:$C$404,0)) -> Increasing | J35: =VLOOKUP($B35,Reliability!$A$3:$I$300,9,FALSE) -> Very High | K35: =IF(OR(M35="x",L35="x"),"x",(10-GEOMEAN(((10-L35)/10*9+1),((10-M35)/10*9+1),((10-M35)/10*9+1)))/9*10) -> 5.5324009 | L35: =VLOOKUP($B35,'Impact of the crisis'!$C$6:$N$300,12,FALSE) -> 4.8242454 | M35: =VLOOKUP($B35,'Impact of the crisis'!$C$6:$AB$300,26,FALSE) -> 5.8559793 | N35: =VLOOKUP($B35,'Conditions of people affected'!$C$6:$R$300,16,FALSE) -> 3.1208829 | O35: =VLOOKUP($B35,'Conditions of people affected'!$C$6:$R$300,9,FALSE) -> 3.5481933 | P35: =VLOOKUP($B35,'Conditions of people affected'!$C$6:$R$300,15,FALSE) -> 2.6935725 | Q35: =IF(OR(S35="x",R35="x"),R35,(10-GEOMEAN(((10-R35)/10*9+1),((10-S35)/10*9+1)))/9*10) -> 3.4674656 | R35: =VLOOKUP($B35,'Complexity of the crisis'!$C$6:$AN$300,22,FALSE) -> 3.4347921 | S35: =VLOOKUP($B35,'Complexity of the crisis'!$C$6:$AN$300,38,FALSE) -> 3.5 | T35: =VLOOKUP(B35,Lists!$C$3:$E$300,3,FALSE) -> Europe | U35: =VLOOKUP(B35,'INFORM Severity - hidden'!$C$5:$V$300,20,FALSE) -> 46265
